Workbook

Sheet Baseline nutritional requiremen
B2: Food Group | C2: Minimum Serve Each Day | D2: Example of a serving size | E2: Good Source Of:
B3: Breads and cereals | C3: eat at least 6 servings | D3: 1 roll 1 muffin 1 medium slice bread 1 cup corn flakes or other breakfast cereal 2 weet bix 1/2 cup museli 1/2 cup porridge 1 cup cooked rice or pasta 2 plain sweet biscuits | E3: carbohydrate fibre B vitamins ( except B12 ) vitamin E calcium iron zinc | G3: ONLY POSITIVITY STAYS AND THE OUTCOMES REPEAT THEMSELVES
B4: Fruit and vegetables | C4: eat at least 2 servings of fruit and 3 servings of vegetables | D4: 1 medium fruit e.g. apple,orange,pear,peach, banana 2 small fruit e.g. plums 1 cup fruit juice 1/4 cup dired fruit e.g. raisins , apricots 1/2 cup raw cooked or canned fruits or veges 1 medium cooked taro , potato or kumara | E4: carbohydrate fibre vitamin A vitamin C ( dried fruit are not as good a source of vitamin C as raw fruit ) folate magnesium potassium
B5: Milk, milk products and milk substitutes | C5: have at least 2 servings | D5: 1 glass ( 250 ml ) milk 1 pottle youghurt 2 slices cheese 2 scoops ice cream 3 table spoons cotage cheese 1 glass ( 250 ml ) soy milk ( calcium fortified ) | E5: protein calcium carbohydrate ( milk and yoghurt ) fat ( saturated ) vitamins , especially B2 and B12 other minerals
B6: Lean meats, poultry, fish, eggs , nuts, pulses | C6: eat at least 1 serve | D6: 2 slices cooked meat 3/4 cup mice or cassarole 1 medium steak 2 drumsticks or 1 chicken leg 1 medium fillet fish 1 egg 1/3 cup nuts or seeds 3/4 cup cooked dried beans 1/2 cup tofu | E6: protein iron fats ( saturated ) carbohydrate ( dried beans/peas) vitamins B1, B12, niacin minerals - zinc , magnesium , copper ,potassium, selenium
B7: Fluids | C7: drink at least 8 cups | D7: water or other fluids

Sheet Baseline Nutrition Checker
A1: Food Group | B1: Minimum Serve Each Day | C1: Example of a serving size | D1: Good Source Of: | E1: Food Eaten | F1: Total Serves
A2: Breads and cereals | B2: eat at least 6 servings | C2: 1 roll 1 muffin 1 medium slice bread 1 cup corn flakes or other breakfast cereal 2 weet bix 1/2 cup museli 1/2 cup porridge 1 cup cooked rice or pasta 2 plain sweet biscuits | D2: carbohydrate fibre B vitamins ( except B12 ) vitamin E calcium iron zinc
A3: Fruit and vegetables | B3: eat at least 2 servings of fruit and 3 servings of vegetables | C3: 1 medium fruit e.g. apple,orange,pear,peach, banana 2 small fruit e.g. plums 1 cup fruit juice 1/4 cup dired fruit e.g. raisins , apricots 1/2 cup raw cooked or canned fruits or veges 1 medium cooked taro , potato or kumara | D3: carbohydrate fibre vitamin A vitamin C ( dried fruit are not as good a source of vitamin C as raw fruit ) folate magnesium potassium
A4: Milk, milk products and milk substitutes | B4: have at least 2 servings | C4: 1 glass ( 250 ml ) milk 1 pottle youghurt 2 slices cheese 2 scoops ice cream 3 table spoons cotage cheese 1 glass ( 250 ml ) soy milk ( calcium fortified ) | D4: protein calcium carbohydrate ( milk and yoghurt ) fat ( saturated ) vitamins , especially B2 and B12 other minerals
A5: Lean meats, poultry, fish, eggs , nuts, pulses | B5: eat at least 1 serve | C5: 2 slices cooked meat 3/4 cup mice or cassarole 1 medium steak 2 drumsticks or 1 chicken leg 1 medium fillet fish 1 egg 1/3 cup nuts or seeds 3/4 cup cooked dried beans 1/2 cup tofu | D5: protein iron fats ( saturated ) carbohydrate ( dried beans/peas) vitamins B1, B12, niacin minerals - zinc , magnesium , copper ,potassium, selenium
A6: Fluids | B6: drink at least 8 cups | C6: water or other fluids

Sheet Rudransh Diet
A1: Weight(kg)= | B1: 71 | D1: Age(years)= | E1: 14
C3: Activity Type | D3: Duration (minutes) | E3: Carbohydrate Needs(grams) | F3: Protein Needs(grams) | G3: Calcium Needs(mg/day) | H3: Fat Needs(g/day) | I3: Iron Needs(mg/day)
B4: School + Training | C4: Running | D4: 120 | E4: =B1*'Nutrition Master'!I5 -> 710 | F4: =B1*'Nutrition Master'!J12 -> 142 | G4: ='Nutrition Master'!B11 -> 1000-1200 | H4: ='Nutrition Master'!B5 -> 70 | I4: ='Nutrition Master'!E2 -> 43751
C5: Tennis | D5: 60-120 | E5: =B1*'Nutrition Master'!I4 -> 568 | F5: =B1*'Nutrition Master'!J12 -> 142 | H5: =H4 -> 70 | I5: =I4 -> 43751
D8: Total: | E8: =sum(E4:E7) -> 1278 | F8: =sum(F4:F7) -> 284 | G8: =G4 -> 1000-1200 | H8: =H4 -> 70 | I8: =I4 -> 43751
B10: School Only | C10: Running | D10: 120 | E10: =B1*'Nutrition Master'!I5 -> 710 | F10: =B1*'Nutrition Master'!J12 -> 142 | G10: ='Nutrition Master'!B11 -> 1000-1200 | H10: ='Nutrition Master'!B5 -> 70 | I10: ='Nutrition Master'!E2 -> 43751
D13: Total: | E13: =sum(E10:E12) -> 710 | F13: =sum(F10:F12) -> 142 | G13: =G10 -> 1000-1200 | H13: =H10 -> 70 | I13: =I10 -> 43751
C20: Note : Review the nutrition requirement by following Nutrition Master every year or 7 days before tournament day
A34: 21/7/2026 | C34: Protein | D34: Energy(Kcal) | E34: Fat | F34: Carbohydrate
B35: Goal: | C35: 157 | D35: 2800 | E35: 90 | F35: 290
B36: Amount left to eat: | C36: 90.05 | D36: 1358.27 | E36: 17.86 | F36: 146.69
B38: 16/9/2026
A40: 16/9/2026 | C40: Protein | D40: Energy(Kcal) | E40: Fat | F40: Carbohydrate
B41: Goal: | C41: 157 | D41: 2800 | E41: 90 | F41: 290
B42: Amount left to eat: | C42: 114.2 | D42: 1956 | E42: 40.75 | F42: 228.75
A46: 17/9/2026 | C46: Protein | D46: Energy(Kcal) | E46: Fat | F46: Carbohydrate
B47: Goal: | C47: 157 | D47: 2800 | E47: 90 | F47: 290
B48: Amount left to eat: | C48: -15.09 | D48: -547.13 | E48: -53.58 | F48: 40.19
A52: 18/9/2026 | C52: Protein | D52: Energy(Kcal) | E52: Fat | F52: Carbohydrate
B53: Goal: | C53: 157 | D53: 2800 | E53: 90 | F53: 290
B54: Amount left to eat: | C54: 33.9 | D54: 277.08 | E54: -12.9 | F54: 89.2
A58: 19/9/2026 | C58: Protein | D58: Energy(Kcal) | E58: Fat | F58: Carbohydrate
B59: Goal: | C59: 157 | D59: 2800 | E59: 90 | F59: 290
B60: Amount left to eat: | C60: 30 | D60: 234 | E60: -24.8 | F60: 35
A64: 21/9/2026 | C64: Protein | D64: Energy(Kcal) | E64: Fat | F64: Carbohydrate
B65: Goal: | C65: 157 | D65: 2800 | E65: 90 | F65: 290
B66: Amount left to eat: | C66: 50.8 | D66: 1145.2 | E66: -27.2 | F66: 253.2
A70: 22/9/2026 | C70: Protein | D70: Energy(Kcal) | E70: Fat | F70: Carbohydrate
B71: Goal: | C71: 157 | D71: 2800 | E71: 90 | F71: 290
B72: Amount left to eat: | C72: 57.56 | D72: 493.1 | E72: -22.12 | F72: 64.26
A76: 23/9/2026 | C76: Protein | D76: Energy(Kcal) | E76: Fat | F76: Carbohydrate
B77: Goal: | C77: 157 | D77: 2800 | E77: 90 | F77: 290
B78: Amount left to eat: | C78: 47 | D78: 563.8 | E78: -24.138 | F78: 99.222
A82: 24/9/2026 | C82: Protein | D82: Energy(Kcal) | E82: Fat | F82: Carbohydrate
B83: Goal: | C83: 157 | D83: 2800 | E83: 90 | F83: 290
B84: Amount left to eat: | C84: 10 | D84: -263 | E84: -25 | F84: -226
A88: 25/9/2026 | C88: Protein | D88: Energy(Kcal) | E88: Fat | F88: Carbohydrate
B89: Goal: | C89: 157 | D89: 2800 | E89: 90 | F89: 290
B90: Amount left to eat: | C90: 52 | D90: 631 | E90: -33 | F90: 128
A94: 26/9/2026 | C94: Protein | D94: Energy(Kcal) | E94: Fat | F94: Carbohydrate
...

Sheet Rudransh Protein Foods
A1: Serving Unit in Grams | B1: 100 | E1: Ideal Protein Per Day | F1: I can eat per day | J1: Weight(kg)= | K1: 71
E2: =K1*'Nutrition Master'!J12 -> 142 | F2: 80
G3: 46107 | H3: 46108 | I3: 46111 | J3: 46112 | K3: 46114 | L3: 46126 | M3: 46127 | N3: 46107 | O3: 46063 | P3: 46111 | Q3: 46112 | R3: 46114 | S3: 46126 | T3: 46127 | V3: 46107 | W3: 46146 | X3: 46111 | Y3: 46112 | Z3: 46114 | AA3: 46126 | AB3: 46127 | AC3: 46107 | AD3: 46146 | AE3: 46111 | AF3: 46112 | AG3: 46114 | AH3: 46126 | AI3: 46127
A4: Protien Food | B4: Protein Per 100 Grams | C4: Quantity To Get 142 Grams | D4: Serving Size ( Grams ) | E4: I Eat In Grams | F4: Protein I Take | G4: Serving I Ate | H4: Serving I Ate | I4: Serving I Ate | J4: Serving I Ate | K4: Serving I Ate | L4: Serving I Ate | M4: Serving I Ate | N4: Protein I Ate | O4: Protein I Ate | P4: Protein I Ate | Q4: Protein I Ate | R4: Protein I Ate | S4: Protein I Ate | T4: Protein I Ate | V4: Serving I Ate | W4: Serving I Ate | X4: Serving I Ate | Y4: Serving I Ate | Z4: Serving I Ate | AA4: Serving I Ate | AB4: Serving I Ate | AC4: Protein I Ate | AD4: Protein I Ate | AE4: Protein I Ate | AF4: Protein I Ate | AG4: Protein I Ate | AH4: Protein I Ate | AI4: Protein I Ate
A5: Milk | B5: 3.2 | C5: =E2/B5*B1 -> 4437.5 | D5: 500 | E5: 1250 | F5: =E5/B1*B5 -> 40 | G5: 290 | H5: 1000 | I5: 500 | J5: 1100 | K5: 1100 | L5: 1000 | M5: 500 | N5: =G5*($B5/$B$1) -> 9.28 | O5: =H5*($B5/$B$1) -> 32 | P5: =I5*($B5/$B$1) -> 16 | Q5: =J5*($B5/$B$1) -> 35.2 | R5: =K5*($B5/$B$1) -> 35.2 | S5: =L5*($B5/$B$1) -> 32 | T5: =M5*($B5/$B$1) -> 16 | V5: 500 | W5: 500 | AC5: =V5*($B5/$B$1) -> 16 | AD5: =W5*($B5/$B$1) -> 16 | AE5: =X5*($B5/$B$1) -> 0 | AF5: =Y5*($B5/$B$1) -> 0 | AG5: =Z5*($B5/$B$1) -> 0 | AH5: =AA5*($B5/$B$1) -> 0 | AI5: =AB5*($B5/$B$1) -> 0
A6: Youghurt | B6: 3.8 | C6: =Round((E2/B6*B1),2) -> 3736.84 | D6: 250 | E6: 250 | F6: =E6/B1*B6 -> 9.5 | J6: 100 | N6: =G6*($B6/$B$1) -> 0 | O6: =H6*($B6/$B$1) -> 0 | P6: =I6*($B6/$B$1) -> 0 | Q6: =J6*($B6/$B$1) -> 3.8 | R6: =K6*($B6/$B$1) -> 0 | S6: =L6*($B6/$B$1) -> 0 | T6: =M6*($B6/$B$1) -> 0 | AC6: =V6*($B6/$B$1) -> 0 | AD6: =W6*($B6/$B$1) -> 0 | AE6: =X6*($B6/$B$1) -> 0 | AF6: =Y6*($B6/$B$1) -> 0 | AG6: =Z6*($B6/$B$1) -> 0 | AH6: =AA6*($B6/$B$1) -> 0 | AI6: =AB6*($B6/$B$1) -> 0
A7: Slices cheese | B7: 20 | C7: =Round((E2/B7*B1),2) -> 710 | D7: 40 | E7: 80 | F7: =E7/B1*B7 -> 16 | G7: 80 | H7: 80 | I7: 80 | J7: 80 | K7: 80 | L7: 80 | M7: 80 | N7: =G7*($B7/$B$1) -> 16 | O7: =H7*($B7/$B$1) -> 16 | P7: =I7*($B7/$B$1) -> 16 | Q7: =J7*($B7/$B$1) -> 16 | R7: =K7*($B7/$B$1) -> 16 | S7: =L7*($B7/$B$1) -> 16 | T7: =M7*($B7/$B$1) -> 16 | V7: 80 | W7: 40 | AC7: =V7*($B7/$B$1) -> 16 | AD7: =W7*($B7/$B$1) -> 8 | AE7: =X7*($B7/$B$1) -> 0 | AF7: =Y7*($B7/$B$1) -> 0 | AG7: =Z7*($B7/$B$1) -> 0 | AH7: =AA7*($B7/$B$1) -> 0 | AI7: =AB7*($B7/$B$1) -> 0
A8: Paneer | B8: 19 | C8: =Round((E2/B8*B1),2) -> 747.37 | N8: =G8*($B8/$B$1) -> 0 | O8: =H8*($B8/$B$1) -> 0 | P8: =I8*($B8/$B$1) -> 0 | Q8: =J8*($B8/$B$1) -> 0 | R8: =K8*($B8/$B$1) -> 0 | S8: =L8*($B8/$B$1) -> 0 | T8: =M8*($B8/$B$1) -> 0 | AC8: =V8*($B8/$B$1) -> 0 | AD8: =W8*($B8/$B$1) -> 0 | AE8: =X8*($B8/$B$1) -> 0 | AF8: =Y8*($B8/$B$1) -> 0 | AG8: =Z8*($B8/$B$1) -> 0 | AH8: =AA8*($B8/$B$1) -> 0 | AI8: =AB8*($B8/$B$1) -> 0
A9: Razma | B9: 8.7 | C9: =Round((E2/B9*B1),2) -> 1632.18 | N9: =G9*($B9/$B$1) -> 0 | O9: =H9*($B9/$B$1) -> 0 | P9: =I9*($B9/$B$1) -> 0 | Q9: =J9*($B9/$B$1) -> 0 | R9: =K9*($B9/$B$1) -> 0 | S9: =L9*($B9/$B$1) -> 0 | T9: =M9*($B9/$B$1) -> 0 | AC9: =V9*($B9/$B$1) -> 0 | AD9: =W9*($B9/$B$1) -> 0 | AE9: =X9*($B9/$B$1) -> 0 | AF9: =Y9*($B9/$B$1) -> 0 | AG9: =Z9*($B9/$B$1) -> 0 | AH9: =AA9*($B9/$B$1) -> 0 | AI9: =AB9*($B9/$B$1) -> 0
A10: Dal | B10: 9 | C10: =Round((E2/B10*B1),2) -> 1577.78 | N10: =G10*($B10/$B$1) -> 0 | O10: =H10*($B10/$B$1) -> 0 | P10: =I10*($B10/$B$1) -> 0 | Q10: =J10*($B10/$B$1) -> 0 | R10: =K10*($B10/$B$1) -> 0 | S10: =L10*($B10/$B$1) -> 0 | T10: =M10*($B10/$B$1) -> 0 | W10: 168 | AC10: =V10*($B10/$B$1) -> 0 | AD10: =W10*($B10/$B$1) -> 15.12 | AE10: =X10*($B10/$B$1) -> 0 | AF10: =Y10*($B10/$B$1) -> 0 | AG10: =Z10*($B10/$B$1) -> 0 | AH10: =AA10*($B10/$B$1) -> 0 | AI10: =AB10*($B10/$B$1) -> 0
A11: Bread | B11: 7.7 | C11: =Round((E2/B11*B1),2) -> 1844.16 | D11: 60 | E11: 120 | F11: =E11/B1*B11 -> 9.24 | G11: 120 | H11: 120 | K11: 120 | L11: 180 | N11: =G11*($B11/$B$1) -> 9.24 | O11: =H11*($B11/$B$1) -> 9.24 | P11: =I11*($B11/$B$1) -> 0 | Q11: =J11*($B11/$B$1) -> 0 | R11: =K11*($B11/$B$1) -> 9.24 | S11: =L11*($B11/$B$1) -> 13.86 | T11: =M11*($B11/$B$1) -> 0 | V11: 180 | W11: 60 | AC11: =V11*($B11/$B$1) -> 13.86 | AD11: =W11*($B11/$B$1) -> 4.62 | AE11: =X11*($B11/$B$1) -> 0 | AF11: =Y11*($B11/$B$1) -> 0 | AG11: =Z11*($B11/$B$1) -> 0 | AH11: =AA11*($B11/$B$1) -> 0 | AI11: =AB11*($B11/$B$1) -> 0
A12: Kellogs Choco | B12: 9 | C12: =Round((E2/B12*B1),2) -> 1577.78 | D12: 35 | E12: 35 | F12: =E12/B1*B12 -> 3.15 | G12: 35 | H12: 35 | I12: 35 | J12: 35 | L12: 30 | M12: 30 | N12: =G12*($B12/$B$1) -> 3.15 | O12: =H12*($B12/$B$1) -> 3.15 | P12: =I12*($B12/$B$1) -> 3.15 | Q12: =J12*($B12/$B$1) -> 3.15 | R12: =K12*($B12/$B$1) -> 0 | S12: =L12*($B12/$B$1) -> 2.7 | T12: =M12*($B12/$B$1) -> 2.7 | AC12: =V12*($B12/$B$1) -> 0 | AD12: =W12*($B12/$B$1) -> 0 | AE12: =X12*($B12/$B$1) -> 0 | AF12: =Y12*($B12/$B$1) -> 0 | AG12: =Z12*($B12/$B$1) -> 0 | AH12: =AA12*($B12/$B$1) -> 0 | AI12: =AB12*($B12/$B$1) -> 0
A13: Chapati | B13: 7.5 | C13: =Round((E2/B13*B1),2) -> 1893.33 | E13: 80 | F13: =E13/B1*B13 -> 6 | G13: 80 | J13: 40 | N13: =G13*($B13/$B$1) -> 6 | O13: =H13*($B13/$B$1) -> 0 | P13: =I13*($B13/$B$1) -> 0 | Q13: =J13*($B13/$B$1) -> 3 | R13: =K13*($B13/$B$1) -> 0 | S13: =L13*($B13/$B$1) -> 0 | T13: =M13*($B13/$B$1) -> 0 | AC13: =V13*($B13/$B$1) -> 0 | AD13: =W13*($B13/$B$1) -> 0 | AE13: =X13*($B13/$B$1) -> 0 | AF13: =Y13*($B13/$B$1) -> 0 | AG13: =Z13*($B13/$B$1) -> 0 | AH13: =AA13*($B13/$B$1) -> 0 | AI13: =AB13*($B13/$B$1) -> 0
A14: Panneer Curry | B14: 25 | I14: 100 | N14: =G14*($B14/$B$1) -> 0 | O14: =H14*($B14/$B$1) -> 0 | P14: =I14*($B14/$B$1) -> 25 | Q14: =J14*($B14/$B$1) -> 0 | R14: =K14*($B14/$B$1) -> 0 | S14: =L14*($B14/$B$1) -> 0 | T14: =M14*($B14/$B$1) -> 0 | AC14: =V14*($B14/$B$1) -> 0 | AD14: =W14*($B14/$B$1) -> 0 | AE14: =X14*($B14/$B$1) -> 0 | AF14: =Y14*($B14/$B$1) -> 0 | AG14: =Z14*($B14/$B$1) -> 0 | AH14: =AA14*($B14/$B$1) -> 0 | AI14: =AB14*($B14/$B$1) -> 0
A15: Protein bar | B15: 25 | C15: =Round((E2/B15*B1),2) -> 568 | D15: 40 | E15: 80 | F15: =E15/B1*B15 -> 20 | G15: 80 | H15: 80 | J15: 40 | K15: 100 | L15: 80 | N15: =G15*($B15/$B$1) -> 20 | O15: =H15*($B15/$B$1) -> 20 | P15: =I15*($B15/$B$1) -> 0 | Q15: =J15*($B15/$B$1) -> 10 | R15: =K15*($B15/$B$1) -> 25 | S15: =L15*($B15/$B$1) -> 20 | T15: =M15*($B15/$B$1) -> 0 | W15: 40 | AC15: =V15*($B15/$B$1) -> 0 | AD15: =W15*($B15/$B$1) -> 10 | AE15: =X15*($B15/$B$1) -> 0 | AF15: =Y15*($B15/$B$1) -> 0 | AG15: =Z15*($B15/$B$1) -> 0 | AH15: =AA15*($B15/$B$1) -> 0 | AI15: =AB15*($B15/$B$1) -> 0
A16: Meusli | B16: 24 | C16: =Round((E2/B16*B1),2) -> 591.67 | D16: 40 | E16: 40 | F16: =E16/B1*B16 -> 9.6 | G16: 50 | H16: 50 | I16: 70 | J16: 80 | L16: 70 | M16: 70 | N16: =G16*($B16/$B$1) -> 12 | O16: =H16*($B16/$B$1) -> 12 | P16: =I16*($B16/$B$1) -> 16.8 | Q16: =J16*($B16/$B$1) -> 19.2 | R16: =K16*($B16/$B$1) -> 0 | S16: =L16*($B16/$B$1) -> 16.8 | T16: =M16*($B16/$B$1) -> 16.8 | V16: 70 | W16: 90 | AC16: =V16*($B16/$B$1) -> 16.8 | AD16: =W16*($B16/$B$1) -> 21.6 | AE16: =X16*($B16/$B$1) -> 0 | AF16: =Y16*($B16/$B$1) -> 0 | AG16: =Z16*($B16/$B$1) -> 0 | AH16: =AA16*($B16/$B$1) -> 0 | AI16: =AB16*($B16/$B$1) -> 0
A25: Total Protein | F25: =sum(F5:F16) -> 113.49 | N25: =round(sum(N5:N24),2) -> 75.67 | O25: =round(sum(O5:O24),2) -> 92.39 | P25: =round(sum(P5:P24),2) -> 76.95 | Q25: =round(sum(Q5:Q24),2) -> 90.35 | R25: =round(sum(R5:R24),2) -> 85.44 | S25: =round(sum(S5:S24),2) -> 101.36 | T25: =round(sum(T5:T24),2) -> 51.5 | AC25: =ROUND(SUM(AC5:AC24),2) -> 62.66 | AD25: =ROUND(SUM(AD5:AD24),2) -> 75.34 | AE25: =ROUND(SUM(AE5:AE24),2) -> 0 | AF25: =ROUND(SUM(AF5:AF24),2) -> 0 | AG25: =ROUND(SUM(AG5:AG24),2) -> 0 | AH25: =ROUND(SUM(AH5:AH24),2) -> 0 | AI25: =ROUND(SUM(AI5:AI24),2) -> 0
C31: Breakfast | D31: Lunch | E31: Dinner
B32: Protein goal: | C32: =E2*(3/6) -> 71 | D32: =ROUND(E2*(2/6),0) -> 47 | E32: =ROUND(E2*(1/6),0) -> 24
C42: Amount eaten
C110: 520 gms= total panneer in the paratha filling
G117: DATA FOR TODAY | O117: DATA FOR TODAY(INDIVIDUALY)
B118: Food | C118: Amount eaten (gms) | G118: Protein | H118: Energy(Kcal) | I118: Fat | J118: Carbohydrate
B119: MILK | C119: 500 | G119: =SUM(Q125,T125,W125,Z125,Q134,T134,W134,T143,W143,Z143,Q152,T152,W152,Z152) -> 90.66 | H119: =SUM(Q122,T122,W122,Z122,Q131,T131,W131,T140,W140,Z140,Q149,T149,W149,Z149) -> 1861.29 | I119: =SUM(Q123,T123,W123,Z123,Q132,T132,W132,T141,W141,T150,Z141,Q150,W150,Z150) -> 101.16 | J119: =SUM(Q124,T124,W124,Z124,Q133,T133,W133,T142,W142,Z142,Q151,T151,W151,Z151) -> 153.5 | P119: MILK | S119: Yoghurt | V119: Cheese | Y119: Paneer
B120: Yoghurt
B121: Cheese | P121: Amount | S121: Amount | V121: Amount | Y121: Amount
B122: Paneer | C122: 244 | P122: Energy (Kcal) | Q122: =('Food profiles'!C5/100)*C119 -> 435 | S122: Energy (Kcal) | T122: =('Food profiles'!F5/100)*$C$120 -> 0 | V122: Energy (Kcal) | W122: =('Food profiles'!I5/100)*$C$121 -> 0 | Y122: Energy (Kcal) | Z122: =('Food profiles'!L5/100)*$C$122 -> 758.84
B123: Rajma | P123: Total fat (g) | Q123: =('Food profiles'!C6/100)*C119 -> 30 | S123: Total fat (g) | T123: =('Food profiles'!F6/100)*$C$120 -> 0 | V123: Total fat (g) | W123: =('Food profiles'!I6/100)*$C$121 -> 0 | Y123: Total fat (g) | Z123: =('Food profiles'!L6/100)*$C$122 -> 61
B124: Dal | G124: Protein | H124: Energy(Kcal) | I124: Fat | J124: Carbohydrate | P124: Carbohydrate (g) | Q124: =('Food profiles'!C7/100)*C119 -> 25 | S124: Carbohydrate (g) | T124: =('Food profiles'!F7/100)*$C$120 -> 0 | V124: Carbohydrate (g) | W124: =('Food profiles'!I7/100)*$C$121 -> 0 | Y124: Carbohydrate (g) | Z124: =('Food profiles'!L7/100)*$C$122 -> 6.1
B125: Bread | C125: 80 | F125: Goal: | G125: 157 | H125: 2800 | I125: 90 | J125: 290 | P125: Protein (g) | Q125: =('Food profiles'!C8/100)*C119 -> 16 | S125: Protein (g) | T125: =('Food profiles'!F8/100)*$C$120 -> 0 | V125: Protein (g) | W125: =('Food profiles'!I8/100)*$C$121 -> 0 | Y125: Protein (g) | Z125: =('Food profiles'!L8/100)*$C$122 -> 46.36
B126: Protein Bar | C126: 55 | F126: Amount left to eat: | G126: =G125-G119 -> 66.34 | H126: =H125-H119 -> 938.71 | I126: =I125-I119 -> -11.16 | J126: =J125-J119 -> 136.5
B127: Muesli
B128: Rice | C128: 200 | P128: Rajma | S128: Dal | V128: Bread
B129: Epigamia protein drink
B130: Protein bread | P130: Amount | S130: Amount | V130: Amount
B131: Dosa | P131: Energy (Kcal) | Q131: =('Food profiles'!C14/100)*$C$123 -> 0 | S131: Energy (Kcal) | T131: =('Food profiles'!F14/100)*$C$124 -> 0 | V131: Energy (Kcal) | W131: =('Food profiles'!I14/100)*$C$125 -> 188
B132: Egg | P132: Total fat (g) | Q132: =('Food profiles'!C15/100)*$C$123 -> 0 | S132: Total fat (g) | T132: =('Food profiles'!F15/100)*$C$124 -> 0 | V132: Total fat (g) | W132: =('Food profiles'!I15/100)*$C$125 -> 0.96
P133: Carbohydrate (g) | Q133: =('Food profiles'!C16/100)*$C$123 -> 0 | S133: Carbohydrate (g) | T133: =('Food profiles'!F16/100)*$C$124 -> 0 | V133: Carbohydrate (g) | W133: =('Food profiles'!I16/100)*$C$125 -> 40
P134: Protein (g) | Q134: =('Food profiles'!C17/100)*$C$123 -> 0 | S134: Protein (g) | T134: =('Food profiles'!F17/100)*$C$124 -> 0 | V134: Protein (g) | W134: =('Food profiles'!I17/100)*$C$125 -> 6.4
S137: Protein bar | V137: Meusli | Y137: Rice
...

Sheet Food profiles
B2: MILK | E2: Yoghurt | H2: Cheese | K2: Paneer
B4: Amount per 100 ml | E4: Amount per 100 ml | H4: Amount per 100 gm | K4: Amount per 100 gm
B5: Energy (Kcal) | C5: 87 | E5: Energy (Kcal) | F5: 63 | H5: Energy (Kcal) | I5: 314 | K5: Energy (Kcal) | L5: 311
B6: Total fat (g) | C6: 6 | E6: Total fat (g) | F6: 3 | H6: Total fat (g) | I6: 26 | K6: Total fat (g) | L6: 25
B7: Carbohydrate (g) | C7: 5 | E7: Carbohydrate (g) | F7: 5 | H7: Carbohydrate (g) | I7: 1.5 | K7: Carbohydrate (g) | L7: 2.5
B8: Protein (g) | C8: 3.2 | E8: Protein (g) | F8: 3.8 | H8: Protein (g) | I8: 20 | K8: Protein (g) | L8: 19
B11: Rajma | E11: Dal | H11: Bread | K11: Paratha
B13: Amount per 100 gm | E13: Amount per 100 ml | H13: Amount per 100 gm | K13: Amount per 100 gm
B14: Energy (Kcal) | C14: 127 | E14: Energy (Kcal) | F14: 127 | H14: Energy (Kcal) | I14: 235 | K14: Energy (Kcal) | L14: 235
B15: Total fat (g) | C15: 2.2 | E15: Total fat (g) | F15: 2.5 | H15: Total fat (g) | I15: 1.2 | K15: Total fat (g) | L15: 1.2
B16: Carbohydrate (g) | C16: 22.8 | E16: Carbohydrate (g) | F16: 20 | H16: Carbohydrate (g) | I16: 50 | K16: Carbohydrate (g) | L16: 50
B17: Protein (g) | C17: 8.7 | E17: Protein (g) | F17: 9 | H17: Protein (g) | I17: 8 | K17: Protein (g) | L17: 8
B20: Paneer Curry | E20: Protein Bar | H20: Muesli | K20: Rice
B22: Amount per 100 gm | E22: Amount per 100 gm | H22: Amount per 100 gm | K22: Amount per 100 gm
B23: Energy (Kcal) | C23: 195 | E23: Energy (Kcal) | F23: 399 | H23: Energy (Kcal) | I23: 400 | K23: Energy (Kcal) | L23: 130
B24: Total fat (g) | C24: 1.2 | E24: Total fat (g) | F24: 16 | H24: Total fat (g) | I24: 8.2 | K24: Total fat (g) | L24: 0.2
B25: Carbohydrate (g) | C25: 50 | E25: Carbohydrate (g) | F25: 48 | H25: Carbohydrate (g) | I25: 64.5 | K25: Carbohydrate (g) | L25: 28
B26: Protein (g) | C26: 8 | E26: Protein (g) | F26: 30 | H26: Protein (g) | I26: 20.3 | K26: Protein (g) | L26: 2.7
B29: Epigamia protein drink | E29: Protein Bread | H29: Dosa | K29: Egg
B31: Amount per 100 gm | E31: Amount per 100 gm | H31: Amount per 100 gm | K31: Amount per egg
B32: Energy (Kcal) | C32: 53.6 | E32: Energy (Kcal) | F32: 287 | H32: Energy (Kcal) | I32: 209 | K32: Energy (Kcal) | L32: 64
B33: Total fat (g) | C33: 0.1 | E33: Total fat (g) | F33: 4.2 | H33: Total fat (g) | I33: 4 | K33: Total fat (g) | L33: 4.2
B34: Carbohydrate (g) | C34: 3.2 | E34: Carbohydrate (g) | F34: 43.34 | H34: Carbohydrate (g) | I34: 37 | K34: Carbohydrate (g) | L34: 0.4
B35: Protein (g) | C35: 10 | E35: Protein (g) | F35: 15.33 | H35: Protein (g) | I35: 5.7 | K35: Protein (g) | L35: 6.2

Sheet Rashmi Diet
A1: Weight(kg)= | B1: 66 | D1: Age(years)= | E1: 34
C3: Activity Type | D3: Duration (minutes) | E3: Carbohydrate Needs(grams) | F3: Protein Needs(grams) | G3: Calcium Needs(mg/day) | H3: Fat Needs(g/day) | I3: Iron Needs(mg/day)
B4: Office + Training | C4: Office Work | E4: =B1*'Nutrition Master'!I2 -> 264 | F4: =B1*'Nutrition Master'!J12 -> 132 | G4: ='Nutrition Master'!B12 -> 800-1000 | H4: ='Nutrition Master'!B3 -> 30-50 | I4: ='Nutrition Master'!E3 -> 43815
C5: Tennis | D5: 60-120 | E5: =B1*'Nutrition Master'!I4 -> 528 | F5: =B1*'Nutrition Master'!J12 -> 132 | H5: =H4 -> 30-50 | I5: =I4 -> 43815
D8: Total: | E8: =sum(E4:E7) -> 792 | F8: =sum(F4:F7) -> 264 | G8: =G4 -> 800-1000 | H8: =H4 -> 30-50 | I8: =I4 -> 43815
B10: Office Only | C10: Office Work | E10: =B1*'Nutrition Master'!I2 -> 264 | F10: =B1*'Nutrition Master'!J12 -> 132 | G10: ='Nutrition Master'!B12 -> 800-1000 | H10: ='Nutrition Master'!B3 -> 30-50 | I10: ='Nutrition Master'!E3 -> 43815
D13: Total: | E13: =sum(E10:E12) -> 264 | F13: =sum(F10:F12) -> 132 | G13: =G10 -> 800-1000 | H13: =H10 -> 30-50 | I13: =I10 -> 43815
C20: Note : Review the nutrition requirement by following Nutrition Master every year
C22: Meeting basic nutrition needs will provide an appropriate carbohydrate intake. You will still need to allow for pre- and post-training needs, e.g. pre- and post- training snacks.

Sheet Krishan Diet
A1: Weight(kg)= | B1: 71 | D1: Age(years)= | E1: 37
C3: Activity Type | D3: Duration (minutes) | E3: Carbohydrate Needs(grams) | F3: Protein Needs(grams) | G3: Calcium Needs(mg/day) | H3: Fat Needs(g/day) | I3: Iron Needs(mg/day) | K3: Note : Review the nutrition requirement by following Nutrition Master every year
B4: Office + Training | C4: Office Work | E4: =B1*'Nutrition Master'!I2 -> 284 | F4: =B1*'Nutrition Master'!J12 -> 142 | G4: ='Nutrition Master'!B12 -> 800-1000 | H4: ='Nutrition Master'!B3 -> 30-50 | I4: ='Nutrition Master'!E3 -> 43815
C5: Tennis | D5: 60-120 | E5: =B1*'Nutrition Master'!I4 -> 568 | F5: =B1*'Nutrition Master'!J12 -> 142 | H5: =H4 -> 30-50 | I5: =I4 -> 43815 | K5: Meeting basic nutrition needs will provide an appropriate carbohydrate intake. You will still need to allow for pre- and post-training needs, e.g. pre- and post- training snacks.
D8: Total: | E8: =sum(E4:E7) -> 852 | F8: =sum(F4:F7) -> 284 | G8: =G4 -> 800-1000 | H8: =H4 -> 30-50 | I8: =I4 -> 43815
B10: Office Only | C10: Office Work | E10: =B1*'Nutrition Master'!I2 -> 284 | F10: =B1*'Nutrition Master'!J12 -> 142 | G10: ='Nutrition Master'!B12 -> 800-1000 | H10: ='Nutrition Master'!B3 -> 30-50 | I10: ='Nutrition Master'!E3 -> 43815
D13: Total: | E13: =sum(E10:E12) -> 284 | F13: =sum(F10:F12) -> 142 | G13: =G10 -> 800-1000 | H13: =H10 -> 30-50 | I13: =I10 -> 43815
B15: Tennis Tournament | C15: Office Work | E15: =B1*'Nutrition Master'!I2 -> 284 | F15: =B1*'Nutrition Master'!J12 -> 142 | G15: ='Nutrition Master'!B12 -> 800-1000 | H15: ='Nutrition Master'!B3 -> 30-50 | I15: ='Nutrition Master'!E3 -> 43815
C16: Tennis | D16: 180-300 | E16: =B1*'Nutrition Master'!I6 -> 710 | F16: =B1*'Nutrition Master'!J12 -> 142 | H16: =H15 -> 30-50 | I16: =I15 -> 43815
D18: Total: | E18: =sum(E15:E17) -> 994 | F18: =sum(F15:F17) -> 284 | G18: =G15 -> 800-1000 | H18: =H15 -> 30-50 | I18: =I15 -> 43815
B20: Cricket Day | C20: Office Work | E20: =B1*'Nutrition Master'!I2 -> 284 | F20: =B1*'Nutrition Master'!J12 -> 142 | G20: ='Nutrition Master'!B12 -> 800-1000 | H20: ='Nutrition Master'!B3 -> 30-50 | I20: ='Nutrition Master'!E3 -> 43815
C21: Cricket | D21: 360-480 | E21: =B1*'Nutrition Master'!I6 -> 710 | F21: =B1*'Nutrition Master'!J12 -> 142 | H21: 30-50 | I21: =I20 -> 43815
D23: Total: | E23: =sum(E20:E22) -> 994 | F23: =sum(F20:F22) -> 284 | G23: 800-1000 | H23: 30-50 | I23: =I20 -> 43815

Sheet Nutrition Master
B1: Fat(grams/day) | D1: Age Group | E1: Iron mg/day | G1: Activity( regular trainining 4-7 days/week ) | H1: Min Grams of carbohydrate per kg of body weight (g/kg) | I1: Max Grams of carbohydrate per kg of body weight (g/kg)
A2: Low-fat diets | B2: 30-40 | D2: Adolescents ( 12-18 yrs ) | E2: 43751 | G2: Sports tha involve low intensity training ( e.g. lawn bowls , croquet ) | H2: Meeting basic nutrition needs will provide an appropriate carbohydrate intake. You will still need to allow for pre- and post-training needs, e.g. pre- and post- training snacks. | I2: 4
A3: Most women and children | B3: 30-50 | D3: Women(19-54 yrs) | E3: 43815 | G3: Sports that involve upto 60 minutes moderate to high intensity training daily ( e.g. golf ) | H3: 5 | I3: 6
A4: Most men | B4: 40-60 | D4: Pregnant women | E4: 22-36 | G4: Sports that involve 60-120 minutes moderate to high intensity training daily ( e.g. sprint training, rugby , soccer, hockey , netball ,short triathlons , racquet sports, cricket , martial arts, throwing sports , sailing, rowing, canoeing, strength and lifting sports) | H4: 7 | I4: 8
A5: Teenagers and active children | B5: 70 | D5: Women ( 54+ yrs ) | E5: 43592 | G5: Endurance training: 2-5 hours of intense training per day ( e.g. distance running, cycling, swimming) | H5: 8 | I5: 10
A6: Larger and very active athletes/workers | B6: 80-100 | D6: Men ( 19+ yrs ) | E6: 7 | G6: Extreme training: more than 5 hours of intense training per day( e.g. Ironman, multisport endurance events) | H6: 10 | I6: 10
G8: Activity | I8: Min Grams of protein per kg of body weight ( g/kg) | J8: Max Grams
G9: General public and athletes taking part in low intensity training | H9: you will meet your protein needs by following the basic nutrition guidelines that provide about 0.8-1 g of protein per kg of body weight each day e.g. lawn bowls,golf,croquet | I9: 0.8 | J9: 1
A10: Age Group | B10: Calcium mg/day | G10: Strength or power training | H10: a protein intake of 1.6-1.7 g/kg/day is recommended you need an increased protein intake combined with apropriate training to enable maximal muscle development e.g. weight training for field sports, body building | I10: 1.6 | J10: 1.7
A11: Adolescents | B11: 1000-1200 | G11: Endurance training | H11: aim for a protein intake of 1.2-1.4 g/kg/day you need an increased protein intake to repair muscle damage caused by excercise such as cycling,distance running | I11: 1.2 | J11: 1.4
A12: Adults (males and females ) | B12: 800-1000 | G12: Adolescent athletes | H12: aim for a protein intake of 2 g/kg/day | I12: 2 | J12: 2
A13: Post-menopausal women | B13: 1000-1200

Sheet Profiling
A1: Section | B1: Task | C1: Status | D1: Notes | E1: Date
A2: 1. Physical Training | B2: Conduct quarterly physical literacy assessment (agility, balance, coordination) | C2: ☐
A3: 1. Physical Training | B3: Adjust training load based on PHV (Peak Height Velocity) status | C3: ☐
A4: 1. Physical Training | B4: Incorporate movement competency drills before heavy loading | C4: ☐
A5: 1. Physical Training | B5: Monitor asymmetries in strength and flexibility during growth spurts | C5: ☐
A6: 1. Physical Training | B6: Track distance covered, sprint counts, high-intensity bursts per session | C6: ☐
A7: 1. Physical Training | B7: Record change of direction efficiency (e.g., 5-10-5 drill times) | C7: ☐
A8: 1. Physical Training | B8: Monitor stroke/skill consistency under fatigue | C8: ☐
A9: 1. Physical Training | B9: Review video analysis for tactical decision-making metrics | C9: ☐
A10: 1. Physical Training | B10: Perform movement screen (e.g., FMS) to identify weak links | C10: ☐
A11: 1. Physical Training | B11: Schedule 2–3 foundational strength sessions per week | C11: ☐
A12: 1. Physical Training | B12: Progress to plyometrics only after adequate strength base | C12: ☐
A13: 1. Physical Training | B13: Include unilateral exercises to correct imbalances | C13: ☐
... A85: 7. Injury Prevention | B85: Schedule at least one full rest day per week | C85: ☐
